<?xml version='1.0' encoding='us-ascii'?>
<mujoco model="articulate_arm"><compiler angle="radian" coordinate="local" /><asset><texture name="grid" type="2d" builtin="checker" width="512" height="512" rgb1="0.9 0.9 0.9" rgb2="0.8 0.8 0.8" /><material name="grid" texture="grid" texrepeat="1 1" texuniform="true" /></asset><worldbody><light pos="0 0 3" directional="true" /><geom name="ground" type="plane" size="1 1 0.01" material="grid" /><body name="link_0" pos="0 0 0.3" euler="-1.5708 0 0"><joint name="joint_0" type="hinge" axis="0 0 1" pos="0 0 0" range="-2.967 2.967" frictionloss="0.1" damping="5.0" /><geom name="link_0_geom" type="capsule" fromto="0 0 0 0.18 0 0" size="0.03" rgba="0.3 0.6 0.9 1" priority="1" /><geom name="link_0_collision" type="capsule" fromto="0 0 0 0.18 0 0" size="0.035" rgba="0 0 0 0" contype="1" conaffinity="1" priority="2" /><inertial pos="0.09 0 0" mass="4.0" fullinertia="0.0018 0.011699999999999999 0.011699999999999999 0 0 0" /><body name="link_1" pos="0.4 0 0" euler="0 0 0"><joint name="joint_1" type="hinge" axis="0 0 1" pos="0 0 0" range="-2.094 2.094" frictionloss="0.1" damping="5.0" /><geom name="link_1_geom" type="capsule" fromto="0 0 0 0.4 0 0" size="0.03" rgba="0.3 0.6 0.9 1" priority="1" /><geom name="link_1_collision" type="capsule" fromto="0 0 0 0.4 0 0" size="0.035" rgba="0 0 0 0" contype="1" conaffinity="1" priority="2" /><inertial pos="0.2 0 0" mass="8.0" fullinertia="0.0036 0.10846666666666668 0.10846666666666668 0 0 0" /><body name="link_2" pos="0.35 0 0" euler="0 0 0"><joint name="joint_2" type="hinge" axis="0 0 1" pos="0 0 0" range="-2.967 2.967" frictionloss="0.1" damping="5.0" /><geom name="link_2_geom" type="capsule" fromto="0 0 0 0.35 0 0" size="0.03" rgba="0.3 0.6 0.9 1" priority="1" /><geom name="link_2_collision" type="capsule" fromto="0 0 0 0.35 0 0" size="0.035" rgba="0 0 0 0" contype="1" conaffinity="1" priority="2" /><inertial pos="0.175 0 0" mass="5.0" fullinertia="0.00225 0.05216666666666666 0.05216666666666666 0 0 0" /><body name="link_3" pos="0 0 0.3" euler="-1.5708 0 0"><joint name="joint_3" type="hinge" axis="0 0 1" pos="0 0 0" range="-2.094 2.094" frictionloss="0.05" damping="5.0" /><geom name="link_3_geom" type="capsule" fromto="0 0 0 0.18 0 0" size="0.03" rgba="0.3 0.6 0.9 1" priority="1" /><geom name="link_3_collision" type="capsule" fromto="0 0 0 0.18 0 0" size="0.035" rgba="0 0 0 0" contype="1" conaffinity="1" priority="2" /><inertial pos="0.09 0 0" mass="2.0" fullinertia="0.0009 0.005849999999999999 0.005849999999999999 0 0 0" /><body name="link_4" pos="0 0 0" euler="1.5708 0 0"><joint name="joint_4" type="hinge" axis="0 0 1" pos="0 0 0" range="-2.967 2.967" frictionloss="0.05" damping="5.0" /><geom name="link_4_geom" type="capsule" fromto="0 0 0 0.1 0 0" size="0.03" rgba="0.3 0.6 0.9 1" priority="1" /><geom name="link_4_collision" type="capsule" fromto="0 0 0 0.1 0 0" size="0.035" rgba="0 0 0 0" contype="1" conaffinity="1" priority="2" /><inertial pos="0.05 0 0" mass="1.5" fullinertia="0.000675 0.0015875000000000004 0.0015875000000000004 0 0 0" /><body name="link_5" pos="0 0 0.1" euler="0 0 0"><joint name="joint_5" type="hinge" axis="0 0 1" pos="0 0 0" range="-2.094 2.094" frictionloss="0.02" damping="5.0" /><geom name="link_5_geom" type="capsule" fromto="0 0 0 0.06 0 0" size="0.03" rgba="0.3 0.6 0.9 1" priority="1" /><geom name="link_5_collision" type="capsule" fromto="0 0 0 0.06 0 0" size="0.035" rgba="0 0 0 0" contype="1" conaffinity="1" priority="2" /><site name="tcp" pos="0.06 0 0" size="0.005" type="sphere" rgba="1 0 0 1" /><inertial pos="0.03 0 0" mass="0.5" fullinertia="0.000225 0.0002625 0.0002625 0 0 0" /></body></body></body></body></body></body></worldbody><actuator><position name="actuator_0" joint="joint_0" kp="20" kv="0.5" forcelimited="true" forcerange="-150.0 150.0" /><position name="actuator_1" joint="joint_1" kp="20" kv="0.5" forcelimited="true" forcerange="-150.0 150.0" /><position name="actuator_2" joint="joint_2" kp="20" kv="0.5" forcelimited="true" forcerange="-100.0 100.0" /><position name="actuator_3" joint="joint_3" kp="20" kv="0.5" forcelimited="true" forcerange="-80.0 80.0" /><position name="actuator_4" joint="joint_4" kp="20" kv="0.5" forcelimited="true" forcerange="-80.0 80.0" /><position name="actuator_5" joint="joint_5" kp="20" kv="0.5" forcelimited="true" forcerange="-50.0 50.0" /></actuator><sensor><jointpos name="jpos_0" joint="joint_0" /><jointvel name="jvel_0" joint="joint_0" /><actuatorfrc name="jtorque_0" actuator="actuator_0" /><jointpos name="jpos_1" joint="joint_1" /><jointvel name="jvel_1" joint="joint_1" /><actuatorfrc name="jtorque_1" actuator="actuator_1" /><jointpos name="jpos_2" joint="joint_2" /><jointvel name="jvel_2" joint="joint_2" /><actuatorfrc name="jtorque_2" actuator="actuator_2" /><jointpos name="jpos_3" joint="joint_3" /><jointvel name="jvel_3" joint="joint_3" /><actuatorfrc name="jtorque_3" actuator="actuator_3" /><jointpos name="jpos_4" joint="joint_4" /><jointvel name="jvel_4" joint="joint_4" /><actuatorfrc name="jtorque_4" actuator="actuator_4" /><jointpos name="jpos_5" joint="joint_5" /><jointvel name="jvel_5" joint="joint_5" /><actuatorfrc name="jtorque_5" actuator="actuator_5" /></sensor><option timestep="0.001" gravity="0 0 -9.81" /><visual><quality shadowsize="4096" /><global offwidth="1280" offheight="720" /></visual></mujoco>