<?xml version='1.0' encoding='us-ascii'?>
<robot name="articulate_arm"><link name="base_link"><visual><geometry><box size="0.2 0.2 0.05" /></geometry></visual><inertial><mass value="5.0" /><inertia ixx="0.1" iyy="0.1" izz="0.1" ixy="0" ixz="0" iyz="0" /></inertial></link><link name="link_0"><visual><geometry><cylinder length="0.18" radius="0.03" /></geometry><origin xyz="0.09 0 0" rpy="0 0 0" /></visual><collision><geometry><cylinder length="0.18" radius="0.03" /></geometry><origin xyz="0.09 0 0" rpy="0 0 0" /></collision><inertial><mass value="4.0" /><inertia ixx="0.0018" iyy="0.011699999999999999" izz="0.011699999999999999" ixy="0" ixz="0" iyz="0" /><origin xyz="0.09 0 0" rpy="0 0 0" /></inertial></link><joint name="joint_0" type="revolute"><parent link="base_link" /><child link="link_0" /><origin xyz="0 0 0.3" rpy="-1.5708 0 0" /><axis xyz="0 0 1" /><limit lower="-2.967" upper="2.967" velocity="2.0" effort="150" /><dynamics friction="0.1" damping="0.05" /></joint><link name="link_1"><visual><geometry><cylinder length="0.4" radius="0.03" /></geometry><origin xyz="0.2 0 0" rpy="0 0 0" /></visual><collision><geometry><cylinder length="0.4" radius="0.03" /></geometry><origin xyz="0.2 0 0" rpy="0 0 0" /></collision><inertial><mass value="8.0" /><inertia ixx="0.0036" iyy="0.10846666666666668" izz="0.10846666666666668" ixy="0" ixz="0" iyz="0" /><origin xyz="0.2 0 0" rpy="0 0 0" /></inertial></link><joint name="joint_1" type="revolute"><parent link="link_0" /><child link="link_1" /><origin xyz="0.4 0 0" rpy="0 0 0" /><axis xyz="0 0 1" /><limit lower="-2.094" upper="2.094" velocity="2.0" effort="150" /><dynamics friction="0.1" damping="0.05" /></joint><link name="link_2"><visual><geometry><cylinder length="0.35" radius="0.03" /></geometry><origin xyz="0.175 0 0" rpy="0 0 0" /></visual><collision><geometry><cylinder length="0.35" radius="0.03" /></geometry><origin xyz="0.175 0 0" rpy="0 0 0" /></collision><inertial><mass value="5.0" /><inertia ixx="0.00225" iyy="0.05216666666666666" izz="0.05216666666666666" ixy="0" ixz="0" iyz="0" /><origin xyz="0.175 0 0" rpy="0 0 0" /></inertial></link><joint name="joint_2" type="revolute"><parent link="link_1" /><child link="link_2" /><origin xyz="0.35 0 0" rpy="0 0 0" /><axis xyz="0 0 1" /><limit lower="-2.967" upper="2.967" velocity="2.5" effort="100" /><dynamics friction="0.1" damping="0.05" /></joint><link name="link_3"><visual><geometry><cylinder length="0.18" radius="0.03" /></geometry><origin xyz="0.09 0 0" rpy="0 0 0" /></visual><collision><geometry><cylinder length="0.18" radius="0.03" /></geometry><origin xyz="0.09 0 0" rpy="0 0 0" /></collision><inertial><mass value="2.0" /><inertia ixx="0.0009" iyy="0.005849999999999999" izz="0.005849999999999999" ixy="0" ixz="0" iyz="0" /><origin xyz="0.09 0 0" rpy="0 0 0" /></inertial></link><joint name="joint_3" type="revolute"><parent link="link_2" /><child link="link_3" /><origin xyz="0 0 0.3" rpy="-1.5708 0 0" /><axis xyz="0 0 1" /><limit lower="-2.094" upper="2.094" velocity="3.0" effort="80" /><dynamics friction="0.05" damping="0.03" /></joint><link name="link_4"><visual><geometry><cylinder length="0.1" radius="0.03" /></geometry><origin xyz="0.05 0 0" rpy="0 0 0" /></visual><collision><geometry><cylinder length="0.1" radius="0.03" /></geometry><origin xyz="0.05 0 0" rpy="0 0 0" /></collision><inertial><mass value="1.5" /><inertia ixx="0.000675" iyy="0.0015875000000000004" izz="0.0015875000000000004" ixy="0" ixz="0" iyz="0" /><origin xyz="0.05 0 0" rpy="0 0 0" /></inertial></link><joint name="joint_4" type="revolute"><parent link="link_3" /><child link="link_4" /><origin xyz="0 0 0" rpy="1.5708 0 0" /><axis xyz="0 0 1" /><limit lower="-2.967" upper="2.967" velocity="3.0" effort="80" /><dynamics friction="0.05" damping="0.03" /></joint><link name="link_5"><visual><geometry><cylinder length="0.06" radius="0.03" /></geometry><origin xyz="0.03 0 0" rpy="0 0 0" /></visual><collision><geometry><cylinder length="0.06" radius="0.03" /></geometry><origin xyz="0.03 0 0" rpy="0 0 0" /></collision><inertial><mass value="0.5" /><inertia ixx="0.000225" iyy="0.0002625" izz="0.0002625" ixy="0" ixz="0" iyz="0" /><origin xyz="0.03 0 0" rpy="0 0 0" /></inertial></link><joint name="joint_5" type="revolute"><parent link="link_4" /><child link="link_5" /><origin xyz="0 0 0.1" rpy="0 0 0" /><axis xyz="0 0 1" /><limit lower="-2.094" upper="2.094" velocity="3.0" effort="50" /><dynamics friction="0.02" damping="0.02" /></joint></robot>